21/11/21 (23:06:10) | ERROR: Data collection thread failed with exception: 'pid'
Traceback (most recent call last):
  File "/usr/bin/bpytop", line 2939, in _runner
    collector._draw()
  File "/usr/bin/bpytop", line 3971, in _draw
    ProcBox._draw_fg()
  File "/usr/bin/bpytop", line 2618, in _draw_fg
    f'{Mv.to(dy-1, x+1)}{THEME.proc_box(Symbol.title_left)}{Fx.b}{THEME.title(str(proc.details["pid"]))}{Fx.ub}{THEME.proc_box(Symbol.title_right)}'
KeyError: 'pid'
21/11/21 (23:06:10) | WARNING: Exiting with errorcode (1). Runtime 0:00:17 

